Workbook

Sheet Summary
A1: Copart (NASDAQ: CPRT) - SHORT
A2: Margin Callers
A3: Horizon: Q1 FY27 through Q2 FY27; planned exit and valuation date mid-February 2027 (after Q2 FY27 results)
A5: Thesis
A6: We are short CPRT because a major insurance-customer loss is creating an FY27 earnings hole that consensus still underestimates. We model $0.37 Q1 EPS and $1.45 FY27 EPS ex-ACV versus $0.41 and $1.62–$1.65 consensus, with Q1/Q2 earnings as the discovery window.
A9: Return profile
A10: Reference price (10/1/26) | B10: =Inputs!$B$6 -> 27.29 | D10: EPS: ours vs consensus
A11: Base-case value (W2) | B11: =Valuation!$B$53 -> 23.103869 | D11: Period (ex-ACV) | E11: Ours | F11: Consensus | G11: Gap
A12: Probability-weighted value | B12: =Valuation!$B$50 -> 24.51619 | D12: Q1 FY27 vs Zacks | E12: =Consensus!B16 -> 0.36739041 | F12: =Consensus!C16 -> 0.41 | G12: =Consensus!D16 -> -0.10392583
A13: Expected short return | B13: =Valuation!$B$52 -> 0.10164201 | D13: FY27 vs S&P Global | E13: =Consensus!B18 -> 1.4520874 | F13: =Consensus!C18 -> 1.62 | G13: =Consensus!D18 -> -0.10364974
A14: Expected short return, EPS-only (no multiple change) | B14: =Valuation!$B$70 -> 0.10260038 | D14: FY27 vs Zacks | E14: =Consensus!B19 -> 1.4520874 | F14: =Consensus!C19 -> 1.65 | G14: =Consensus!D19 -> -0.11994702
A15: W4 adverse-case short loss | B15: =Valuation!$B$55 -> 0.14696287
A16: Rate-cut stress (10Y to 3.5%): short loss | B16: =Valuation!$B$65 -> 0.47072059
A18: Scenarios (Valuation sheet)
A19: World | B19: Probability | C19: FY27 EPS ex-ACV | D19: FY27 GAAP EPS | E19: NTM EPS ex-int. | F19: Justified P/E (NTM) | G19: Value, mid-Feb 27 | H19: Short return
A20: W1 Loss deepens | B20: =Valuation!B8 -> 0.2 | C20: =Valuation!B9 -> 1.2792888 | D20: =Valuation!B11 -> 1.184278 | E20: =Valuation!B24 -> 1.1492474 | F20: =Valuation!B40 -> 12.213675 | G20: =Valuation!B42 -> 17.341255 | H20: =Valuation!B44 -> 0.36455642
A21: W2 FY27 trough / FY28 normalizes | B21: =Valuation!C8 -> 0.45 | C21: =Valuation!C9 -> 1.4520874 | D21: =Valuation!C11 -> 1.3829887 | E21: =Valuation!C24 -> 1.396492 | F21: =Valuation!C40 -> 14.177774 | G21: =Valuation!C42 -> 23.103869 | H21: =Valuation!C44 -> 0.15339433
A22: W3 Cycle turns / ACV improves | B22: =Valuation!D8 -> 0.2 | C22: =Valuation!D9 -> 1.6104159 | D22: =Valuation!D11 -> 1.5672292 | E22: =Valuation!D24 -> 1.6271084 | F22: =Valuation!D40 -> 16.27169 | G22: =Valuation!D42 -> 29.780525 | H22: =Valuation!D44 -> -0.09126146
A23: W4 Street right / share recapture | B23: =Valuation!E8 -> 0.15 | C23: =Valuation!E9 -> 1.7054339 | D23: =Valuation!E11 -> 1.6622472 | E23: =Valuation!E24 -> 1.6976963 | F23: =Valuation!E40 -> 16.490521 | G23: =Valuation!E42 -> 31.300617 | H23: =Valuation!E44 -> -0.14696287
A24: Probability-weighted | G24: =Valuation!$B$50 -> 24.51619 | H24: =Valuation!$B$52 -> 0.10164201
A25: Value at mid-Feb 2027 on NTM (Q3 FY27-Q2 FY28) ex-interest EPS; P/E derived from growth, ROIC and cost of equity (year-specific payouts), not selected. Team scenario probabilities.
A26: Short returns are gross and exclude borrow fees, financing costs and transaction costs.
A27: Catalysts and falsification
A28: Mid-Nov 2026 (estimated) | B28: Q1 FY27: first full quarter reflecting the lost-customer volume impact (U.S. insurance units, OpEx/car, U.S. operating margin).
A29: Mid-Feb 2027 (estimated) | B29: Q2 FY27: second full quarter of lost volume plus first ACV GAAP contribution (model assumes closing during Q2 FY27; company guides close by CY-end 2026). Planned exit and valuation date.
A30: Falsification (Q1 FY27) | B30: Exit if U.S. insurance units are better than −6% y/y, consolidated operating margin ≥36%, or OpEx/car growth ≤ +3% (Catalysts sheet).
A32: Colour key: blue = input; black = formula; green = link to another sheet; red = negative.
A34: Chart data: FY27 quarterly EPS ($/sh), linked to Consensus and EPS_Build
A35: Quarter | B35: Zacks consensus | C35: Margin Callers ex-ACV
A36: Q1 | B36: =Consensus!C5 -> 0.41 | C36: =EPS_Build!B46 -> 0.36739041
A37: Q2 | B37: =Consensus!C6 -> 0.37 | C37: =EPS_Build!C46 -> 0.33206111
A38: Q3 | B38: =Consensus!C7 -> 0.45 | C38: =EPS_Build!D46 -> 0.39611609
A39: Q4 | B39: =Consensus!C8 -> 0.41 | C39: =EPS_Build!E46 -> 0.35651982
A41: Chart data: current-price reference line (linked to Inputs)
A42: Series label | B42: Price ($/sh) | C42: Height
A43: ="Current price "&TEXT(Inputs!$B$6,"$0.00") -> Current price $27.29 | B43: =Inputs!$B$6 -> 27.29 | C43: 0
B44: =Inputs!$B$6 -> 27.29 | C44: 1

Sheet Inputs
A1: Inputs
A2: Blue = hard-coded input; black = formula; green = link. Every input carries a source type; links and SEC accession numbers are on the Sources sheet.
A4: Market, capital structure and tax
A5: Input | B5: Value | C5: Units | D5: Source type | E5: Source / basis
A6: Share price (10/1/26 close) | B6: 27.29 | C6: $/share | D6: Secondary market data | E6: Yahoo Finance daily close, 10/1/26
A7: Diluted shares, FY27 (no net buybacks assumed) | B7: 932 | C7: m shares | D7: Primary + team estimate | E7: Q4 FY26 diluted WASO 932.1m (8-K Ex. 99.1, 9/10/26); 926.3m basic shares outstanding 9/25/26 (10-K cover) + ~5m dilution. No net FY27 buybacks assumed (cash committed to ACV); buyback risk (930m / 920m) and the earlier 940m tested in Sensitivity.
A8: Effective tax rate | B8: 0.195 | C8: % | D8: Primary-derived | E8: FY26 10-K: tax $354.6m / pre-tax $1,835.0m = 19.3%
A9: Cash + restricted cash + HTM securities, 7/31/26 | B9: 4.49 | C9: $bn | D9: Primary | E9: FY26 10-K: $1,907.9m cash, equivalents & restricted + $2,581.9m HTM
A10: Cash + securities at the valuation date (mid-Feb 2027, post-ACV) | B10: 3.08 | C10: $bn | D10: Team estimate | E10: $4.49bn − $1.90bn ACV + ~$0.49bn retained FCF (6.5 months at ~$0.91bn/yr ≈ 72% of FY26 FCF $1.27bn); no buybacks; each ±$0.2bn ≈ ±$0.21/sh
A11: FY26 interest income | B11: 181.9 | C11: $m | D11: Primary | E11: FY26 10-K segment note: interest income $181.9m
A12: Interest income per quarter before ACV close | B12: 38 | C12: $m | D12: Team estimate | E12: Q3/Q4-FY26 actual $38.8m / $39.6m; cash before the ACV payment
A14: ACV transaction timing
A15: Input | B15: Value | C15: Units | D15: Source type | E15: Source / basis
A16: Share of Q2 FY27 (Nov-Jan) with ACV consolidated | B16: 0.5 | C16: % | D16: Team estimate | E16: Model assumes closing during Q2 FY27 (base: mid-Q2, ~Dec 15); company guidance is close by calendar year-end 2026 (10-K; Q4 call). Tender (10/7) and HSR (10/13) milestones are not a close date. Early Q2 = 100%, late Q2 / CY-end = 33% (Sensitivity).
A18: Lost-customer run-rate reconciliation (Q4 FY26)
A19: Input | B19: Value | C19: Units | D19: Source type | E19: Source / basis
A20: Q4 FY26 domestic insurance assignments y/y (reported) | B20: -0.075 | C20: % | D20: Primary (SEC-filed transcript) | E20: Q4 FY26 call (9/10/26; transcript filed as Schedule TO-C Ex. 99.2): domestic insurance assignments −7.5%; CFO: U.S. insurance volumes −7.5%
A21: Q4 FY26 domestic insurance assignments y/y, excluding one lost customer | B21: 0.023 | C21: % | D21: Primary (SEC-filed transcript) | E21: Q4 FY26 call: 'with the exception of 1 single customer loss domestic insurance assignments would be up 2.3%'
A22: Observed Q4 FY26 lost-customer drag (pts) = ex-customer − reported | B22: =B21-B20 -> 0.098 | C22: pts | D22: Derived | E22: +2.3% − (−7.5%) = 9.8 pts; applied as the drag already in the Q4 FY26 base (FY26 segment table below)
A23: W2 full-run-rate drag (pts of U.S. insurance units) | B23: =-Scenarios!$C$7 -> 0.13 | C23: pts | D23: Team estimate | E23: Option A: keep the 13-pt W2 full-run-rate estimate (Scenarios)
A24: Implied share of the W2 run-rate already in Q4 FY26 = 9.8 / 13 | B24: =B22/B23 -> 0.75384615 | C24: % | D24: Derived | E24: ≈75%, replacing the v1 assumption of 60% (which did not reconcile: 9.8 / 13 ≠ 60%). Q1-Q3 FY27 carry the full drag; Q4 FY27 impact = (1 − run-rate) / (1 − 9.8%) − 1 in every world
A25: Full run-rate implied if only 60% was in Q4 FY26 = 9.8 / 0.60 | B25: =B22/0.6 -> 0.16333333 | C25: pts | D25: Derived | E25: ≈16 pts = W1. RB Global's 'probably over the last 90 days' (to 8/4/26) transition suggests ≤60% was in Copart's May-Jul quarter; W2 does not assume this. Tested in Sensitivity (10 / 13 / 16 pts).
A27: Cost of equity
A28: Input | B28: Value | C28: Units | D28: Source type | E28: Source / basis
A29: 10-year U.S. Treasury yield (risk-free) | B29: 0.0524 | C29: % | D29: Primary | E29: U.S. Treasury Daily Par Yield Curve, 10Y on 10/01/2026 = 5.24%
A30: Equity beta | B30: 0.9 | C30: x | D30: Team estimate | E30: Weekly regression of CPRT on SPY, Jul-2023 to Sep-2026 = 0.89 (team calculation); Yahoo 1.03 tested in Sensitivity
A31: Equity risk premium | B31: 0.05 | C31: % | D31: Team estimate | E31: Conventional U.S. ERP assumption; ±0.5pt ERP ≈ ±0.45pt cost of equity (Sensitivity cost-of-equity table)
A32: Terminal growth | B32: 0.03 | C32: % | D32: Team estimate | E32: ≈ long-run nominal U.S. growth; well below CPRT's FY21-FY26 net-income CAGR (~9.7%)
A33: Rate-cut stress: 10-year yield | B33: 0.035 | C33: % | D33: Team estimate | E33: Stress case only (10Y back to 3.5%)
A34: Cost of equity = risk-free + beta × ERP | B34: =B29+B30*B31 -> 0.0974 | C34: % | D34: Derived | E34: CAPM: 5.24% + 0.90 × 5.0% = 9.74%
A35: Stress cost of equity = stress risk-free + beta × ERP | B35: =B33+B30*B31 -> 0.08 | C35: % | D35: Derived | E35: 3.50% + 0.90 × 5.0% = 8.00%
A37: Operating structure (KPI model)
A38: Input | B38: Value | C38: Units | D38: Source type | E38: Source / basis
A39: U.S. insurance share of U.S. units | B39: 0.76 | C39: % | D39: Team estimate | E39: 10-K: insurers supplied 79% of vehicles company-wide; U.S. mix set slightly lower given U.S. dealer/BluCar volume
A40: Fixed share of U.S. facility costs (does not flex with units near term) | B40: 0.55 | C40: % | D40: Team estimate | E40: Q4-FY26 call: U.S. facility costs +7.7% (+14.2% per unit) while U.S. units −5.7% → majority fixed in the short run; 45% / 65% in Sensitivity
A41: U.S. non-insurance unit growth | B41: 0.03 | C41: % | D41: Team estimate | E41: Q4-FY26 U.S. non-insurance +0.2%, dealer units +5.8% (call)
A42: U.S. vehicle gross profit and G&A growth | B42: 0.05 | C42: % | D42: Team estimate | E42: FY26 U.S. G&A +3.7% (10-K segment note); ongoing investment
A43: International operating income and revenue growth | B43: 0.1 | C43: % | D43: Team estimate | E43: FY26 international op. income +8.2%; Q4 international revenue +11.7% (10-K, call)
A45: FY26 quarterly segment actuals ($m) — Primary: 10-Qs Q1-Q3 FY26; Q4 = FY26 10-K less nine months
A46: Line ($m unless stated) | B46: Q1 Aug-Oct | C46: Q2 Nov-Jan | D46: Q3 Feb-Apr | E46: Q4 May-Jul
...

Sheet Scenarios
A1: Scenarios
A2: Four economic worlds: what the market believes → KPIs → earnings → value. Blue = team estimate.
A4: Scenario drivers (all team estimates; basis in the rows below and on Sources)
A5: Driver | B5: W1 Loss deepens | C5: W2 FY27 trough / FY28 normalizes | D5: W3 Cycle turns / ACV improves | E5: W4 Street right / share recapture
A6: Underlying U.S. insurance unit growth, ex lost customer | B6: -0.02 | C6: 0.01 | D6: 0.03 | E6: 0.03
A7: Lost-customer full-run-rate drag (pts of U.S. insurance units) | B7: -0.16 | C7: -0.13 | D7: -0.1 | E7: -0.05
A8: Revenue per unit growth | B8: 0.02 | C8: 0.035 | D8: 0.05 | E8: 0.05
A9: Fixed facility cost growth | B9: 0.1 | C9: 0.07 | D9: 0.04 | E9: 0.04
A10: ACV acquired-intangible amortization per quarter ($m) | B10: 20 | C10: 15 | D10: 10 | E10: 10
A11: ACV operating income per quarter ($m) | B11: -8 | C11: -4 | D11: 0 | E11: 0
A12: Interest income per quarter after ACV close ($m) | B12: 22 | C12: 25 | D12: 28 | E12: 28
A13: FY28 ACV EPS contribution incl. amortization and forgone interest ($/sh) | B13: 0 | C13: 0.02 | D13: 0.04 | E13: 0.02
A14: Team scenario probability | B14: 0.2 | C14: 0.45 | D14: 0.2 | E14: 0.15
A15: FY28 EPS growth (core operating, ex-ACV) | B15: 0.04 | C15: 0.12 | D15: 0.18 | E15: 0.15
A16: EPS growth, 5 years after year 2 | B16: 0.03 | C16: 0.06 | D16: 0.09 | E16: 0.1
A17: Incremental ROIC | B17: 0.15 | C17: 0.2 | D17: 0.25 | E17: 0.25
A18: Probability check (must equal 100%) | B18: =SUM(B14:E14) -> 1
A20: Rationale and evidence (short; sources on Sources sheet)
A21: Item | B21: W1 Loss deepens | C21: W2 FY27 trough / FY28 normalizes | D21: W3 Cycle turns / ACV improves | E21: W4 Street right / share recapture
A22: What each world assumes (evidence) | B22: Loss broadens beyond one customer; ASP softens (Manheim −0.4% y/y mid-Sep, Cox); OpEx/car stays high (+12.7% in Q4, call). 16-pt run-rate ≈ only 60% in the Q4 FY26 base. | C22: The disclosed loss runs at its full 13-pt rate Q1-Q3 FY27 and partly laps in Q4 (~75% already in the Q4 FY26 base). Fixed costs +7%. ACV per model. | D22: Ex-customer insurance units +3% (Q4 ex-customer +2.3%, call); record second-quarter 23.3% total-loss frequency (call). | E22: Share recapture offsets most of the lost volume; published FY27 consensus roughly delivered. Team scenario based on public data only.
A23: Probability rationale (team scenario probabilities; judgmental, not objective) | B23: 20%: plausible but not base. Requires losses beyond the one disclosed customer; management described customer relationships as strong. | C23: 45%: most likely. The only disclosed loss runs at full rate until it laps in Q4 FY27; RB Global indicated substantial incremental partner volume had been transitioning over the prior ~90 days; costs are largely fixed near term (Q4 facility costs +7.7% on units −5.7%). | D23: 20%: record total-loss frequency, rising severity and pricing (U.S. insurance ASP +3.7%) offset the volume hole faster than we model. | E23: 15%: the Street is right. Published FY27 consensus ($1.62-$1.65) implies the loss is largely absorbed; CPRT has historically rebounded after large negative reactions (Checks).
A24: FY28 ACV contribution support | B24: $0.00: accretion guidance not met in FY28. | C24: +$0.02: modestly accretive, consistent with guidance (neutral in the first full year; accretive FY28 and beyond). | D24: +$0.04: synergies arrive faster than guided. | E24: +$0.02: guidance delivered.
A25: 5-year EPS growth (g) support | B25: 3%: pricing-only growth; no unit recovery. | C25: 6%: normalized low-single-digit unit growth plus pricing; below the FY21-FY26 net-income CAGR (~9.7%). | D25: 9%: close to the FY21-FY26 net-income CAGR (~9.7%). | E25: 10%: historical growth resumes.
A26: Incremental ROIC support | B26: 15%: about half of recent core ROIC; lower utilization persists. | C26: 20%: below recent core ROIC (~29-31%, FY25-FY26 NOPAT / equity ex cash & HTM), reflecting lower utilization and ACV mix. | D26: 25%: still below recent core ROIC. | E26: 25%: still below recent core ROIC.

Sheet EPS_Build
A1: FY27 EPS Build (Aug-26 to Jul-27), $m unless stated
A2: Chain: lost-customer impact → U.S. insurance units → U.S. service revenue → operating income → EPS. Model assumes closing during Q2 FY27; company guidance is close by calendar year-end 2026. Q2 ACV P&L and interest are pro-rated by the consolidated share of Q2 (Inputs). Ex-ACV and GAAP-with-ACV kept separate.
A4: W1 Loss deepens
A5: Line | B5: Q1 Aug-Oct | C5: Q2 Nov-Jan | D5: Q3 Feb-Apr | E5: Q4 May-Jul | F5: FY27
A6: Lost-customer impact vs FY26 quarter (pts) | B6: =(1+Scenarios!$B$7)/(1-Inputs!B$55)-1 -> -0.16 | C6: =(1+Scenarios!$B$7)/(1-Inputs!C$55)-1 -> -0.16 | D6: =(1+Scenarios!$B$7)/(1-Inputs!D$55)-1 -> -0.16 | E6: =(1+Scenarios!$B$7)/(1-Inputs!E$55)-1 -> -0.068736142
A7: U.S. insurance units y/y | B7: =Scenarios!$B$6+B6 -> -0.18 | C7: =Scenarios!$B$6+C6 -> -0.18 | D7: =Scenarios!$B$6+D6 -> -0.18 | E7: =Scenarios!$B$6+E6 -> -0.088736142
A8: U.S. units y/y | B8: =Inputs!$B$39*B7+(1-Inputs!$B$39)*Inputs!$B$41 -> -0.1296 | C8: =Inputs!$B$39*C7+(1-Inputs!$B$39)*Inputs!$B$41 -> -0.1296 | D8: =Inputs!$B$39*D7+(1-Inputs!$B$39)*Inputs!$B$41 -> -0.1296 | E8: =Inputs!$B$39*E7+(1-Inputs!$B$39)*Inputs!$B$41 -> -0.060239468
A9: U.S. service revenue ($m) | B9: =Inputs!B$47*(1+B8)*(1+Scenarios!$B$8) -> 759.51974 | C9: =Inputs!C$47*(1+C8)*(1+Scenarios!$B$8) -> 727.55866 | D9: =Inputs!D$47*(1+D8)*(1+Scenarios!$B$8) -> 795.03206 | E9: =Inputs!E$47*(1+E8)*(1+Scenarios!$B$8) -> 783.90689 | F9: =SUM(B9:E9) -> 3066.0174
A10: U.S. vehicle sales ($m) | B10: =Inputs!B$48*(1+Inputs!$B$42) -> 101.955 | C10: =Inputs!C$48*(1+Inputs!$B$42) -> 107.31 | D10: =Inputs!D$48*(1+Inputs!$B$42) -> 112.77 | E10: =Inputs!E$48*(1+Inputs!$B$42) -> 118.125 | F10: =SUM(B10:E10) -> 440.16
A11: U.S. vehicle gross profit ($m) | B11: =(Inputs!B$48-Inputs!B$50)*(1+Inputs!$B$42) -> 7.455 | C11: =(Inputs!C$48-Inputs!C$50)*(1+Inputs!$B$42) -> 6.09 | D11: =(Inputs!D$48-Inputs!D$50)*(1+Inputs!$B$42) -> 8.82 | E11: =(Inputs!E$48-Inputs!E$50)*(1+Inputs!$B$42) -> 7.14
A12: U.S. facility operations ($m) | B12: =Inputs!B$49*Inputs!$B$40*(1+Scenarios!$B$9)+Inputs!B$49*(1-Inputs!$B$40)*(1+B8) -> 397.17698 | C12: =Inputs!C$49*Inputs!$B$40*(1+Scenarios!$B$9)+Inputs!C$49*(1-Inputs!$B$40)*(1+C8) -> 394.08727 | D12: =Inputs!D$49*Inputs!$B$40*(1+Scenarios!$B$9)+Inputs!D$49*(1-Inputs!$B$40)*(1+D8) -> 418.3066 | E12: =Inputs!E$49*Inputs!$B$40*(1+Scenarios!$B$9)+Inputs!E$49*(1-Inputs!$B$40)*(1+E8) -> 432.53705 | F12: =SUM(B12:E12) -> 1642.1079
A13: U.S. G&A ($m) | B13: =Inputs!B$51*(1+Inputs!$B$42) -> 93.66 | C13: =Inputs!C$51*(1+Inputs!$B$42) -> 92.82 | D13: =Inputs!D$51*(1+Inputs!$B$42) -> 98.385 | E13: =Inputs!E$51*(1+Inputs!$B$42) -> 96.285 | F13: =SUM(B13:E13) -> 381.15
A14: U.S. operating income ($m) | B14: =B9+B11-B12-B13 -> 276.13776 | C14: =C9+C11-C12-C13 -> 246.74138 | D14: =D9+D11-D12-D13 -> 287.16047 | E14: =E9+E11-E12-E13 -> 262.22483 | F14: =SUM(B14:E14) -> 1072.2644
A15: U.S. operating margin | B15: =B14/(B9+B10) -> 0.32054075 | C15: =C14/(C9+C10) -> 0.29554515 | D15: =D14/(D9+D10) -> 0.31632498 | E15: =E14/(E9+E10) -> 0.29070461 | F15: =F14/(F9+F10) -> 0.30582151
A16: International operating income ($m) | B16: =Inputs!B$52*(1+Inputs!$B$43) -> 61.27 | C16: =Inputs!C$52*(1+Inputs!$B$43) -> 51.92 | D16: =Inputs!D$52*(1+Inputs!$B$43) -> 81.18 | E16: =Inputs!E$52*(1+Inputs!$B$43) -> 62.48 | F16: =SUM(B16:E16) -> 256.85
A17: International revenue ($m) | B17: =Inputs!B$53*(1+Inputs!$B$43) -> 222.64 | C17: =Inputs!C$53*(1+Inputs!$B$43) -> 220.11 | D17: =Inputs!D$53*(1+Inputs!$B$43) -> 257.62 | E17: =Inputs!E$53*(1+Inputs!$B$43) -> 244.2 | F17: =SUM(B17:E17) -> 944.57
A18: Consolidated operating margin, ex-ACV | B18: =(B14+B16)/(B9+B10+B17) -> 0.31122883 | C18: =(C14+C16)/(C9+C10+C17) -> 0.28309709 | D18: =(D14+D16)/(D9+D10+D17) -> 0.31605757 | E18: =(E14+E16)/(E9+E10+E17) -> 0.28328023 | F18: =(F14+F16)/(F9+F10+F17) -> 0.29862725
A19: Core operating EPS, ex-interest, ex-ACV ($/sh) | B19: =(B14+B16)*(1-Inputs!$B$8)/Inputs!$B$7 -> 0.29143053 | C19: =(C14+C16)*(1-Inputs!$B$8)/Inputs!$B$7 -> 0.25796396 | D19: =(D14+D16)*(1-Inputs!$B$8)/Inputs!$B$7 -> 0.31814815 | E19: =(E14+E16)*(1-Inputs!$B$8)/Inputs!$B$7 -> 0.28045857 | F19: =SUM(B19:E19) -> 1.1480012
A20: Interest income, ex-ACV case ($m) | B20: =Inputs!$B$12 -> 38 | C20: =Inputs!$B$12 -> 38 | D20: =Inputs!$B$12 -> 38 | E20: =Inputs!$B$12 -> 38 | F20: =SUM(B20:E20) -> 152
A21: EPS ex-ACV (operating thesis) | B21: =(B14+B16+B20)*(1-Inputs!$B$8)/Inputs!$B$7 -> 0.32425241 | C21: =(C14+C16+C20)*(1-Inputs!$B$8)/Inputs!$B$7 -> 0.29078585 | D21: =(D14+D16+D20)*(1-Inputs!$B$8)/Inputs!$B$7 -> 0.35097004 | E21: =(E14+E16+E20)*(1-Inputs!$B$8)/Inputs!$B$7 -> 0.31328046 | F21: =SUM(B21:E21) -> 1.2792888
A22: ACV pre-tax: operating income − amortization ($m) | B22: =0 -> 0 | C22: =Inputs!$B$16*(Scenarios!$B$11-Scenarios!$B$10) -> -14 | D22: =Scenarios!$B$11-Scenarios!$B$10 -> -28 | E22: =Scenarios!$B$11-Scenarios!$B$10 -> -28 | F22: =SUM(B22:E22) -> -70
A23: Interest income after ACV cash outflow ($m) | B23: =Inputs!$B$12 -> 38 | C23: =Inputs!$B$16*Scenarios!$B$12+(1-Inputs!$B$16)*Inputs!$B$12 -> 30 | D23: =Scenarios!$B$12 -> 22 | E23: =Scenarios!$B$12 -> 22 | F23: =SUM(B23:E23) -> 112
A24: GAAP EPS incl. ACV | B24: =(B14+B16+B22+B23)*(1-Inputs!$B$8)/Inputs!$B$7 -> 0.32425241 | C24: =(C14+C16+C22+C23)*(1-Inputs!$B$8)/Inputs!$B$7 -> 0.27178371 | D24: =(D14+D16+D22+D23)*(1-Inputs!$B$8)/Inputs!$B$7 -> 0.31296575 | E24: =(E14+E16+E22+E23)*(1-Inputs!$B$8)/Inputs!$B$7 -> 0.27527617 | F24: =SUM(B24:E24) -> 1.184278
A25: ACV EPS impact incl. forgone interest ($/sh) | B25: =B24-B21 -> 0 | C25: =C24-C21 -> -0.019002146 | D25: =D24-D21 -> -0.038004292 | E25: =E24-E21 -> -0.038004292 | F25: =SUM(B25:E25) -> -0.09501073
A26: EPS ex-interest incl. ACV (valuation base, $/sh) | B26: =(B14+B16+B22)*(1-Inputs!$B$8)/Inputs!$B$7 -> 0.29143053 | C26: =(C14+C16+C22)*(1-Inputs!$B$8)/Inputs!$B$7 -> 0.24587169 | D26: =(D14+D16+D22)*(1-Inputs!$B$8)/Inputs!$B$7 -> 0.2939636 | E26: =(E14+E16+E22)*(1-Inputs!$B$8)/Inputs!$B$7 -> 0.25627402 | F26: =SUM(B26:E26) -> 1.0875398
A29: W2 FY27 trough / FY28 normalizes
A30: Line | B30: Q1 Aug-Oct | C30: Q2 Nov-Jan | D30: Q3 Feb-Apr | E30: Q4 May-Jul | F30: FY27
A31: Lost-customer impact vs FY26 quarter (pts) | B31: =(1+Scenarios!$C$7)/(1-Inputs!B$55)-1 -> -0.13 | C31: =(1+Scenarios!$C$7)/(1-Inputs!C$55)-1 -> -0.13 | D31: =(1+Scenarios!$C$7)/(1-Inputs!D$55)-1 -> -0.13 | E31: =(1+Scenarios!$C$7)/(1-Inputs!E$55)-1 -> -0.035476718
A32: U.S. insurance units y/y | B32: =Scenarios!$C$6+B31 -> -0.12 | C32: =Scenarios!$C$6+C31 -> -0.12 | D32: =Scenarios!$C$6+D31 -> -0.12 | E32: =Scenarios!$C$6+E31 -> -0.025476718
A33: U.S. units y/y | B33: =Inputs!$B$39*B32+(1-Inputs!$B$39)*Inputs!$B$41 -> -0.084 | C33: =Inputs!$B$39*C32+(1-Inputs!$B$39)*Inputs!$B$41 -> -0.084 | D33: =Inputs!$B$39*D32+(1-Inputs!$B$39)*Inputs!$B$41 -> -0.084 | E33: =Inputs!$B$39*E32+(1-Inputs!$B$39)*Inputs!$B$41 -> -0.012162306
A34: U.S. service revenue ($m) | B34: =Inputs!B$47*(1+B33)*(1+Scenarios!$C$8) -> 811.06533 | C34: =Inputs!C$47*(1+C33)*(1+Scenarios!$C$8) -> 776.93517 | D34: =Inputs!D$47*(1+D33)*(1+Scenarios!$C$8) -> 848.98773 | E34: =Inputs!E$47*(1+E33)*(1+Scenarios!$C$8) -> 836.12854 | F34: =SUM(B34:E34) -> 3273.1168
A35: U.S. vehicle sales ($m) | B35: =Inputs!B$48*(1+Inputs!$B$42) -> 101.955 | C35: =Inputs!C$48*(1+Inputs!$B$42) -> 107.31 | D35: =Inputs!D$48*(1+Inputs!$B$42) -> 112.77 | E35: =Inputs!E$48*(1+Inputs!$B$42) -> 118.125 | F35: =SUM(B35:E35) -> 440.16
A36: U.S. vehicle gross profit ($m) | B36: =(Inputs!B$48-Inputs!B$50)*(1+Inputs!$B$42) -> 7.455 | C36: =(Inputs!C$48-Inputs!C$50)*(1+Inputs!$B$42) -> 6.09 | D36: =(Inputs!D$48-Inputs!D$50)*(1+Inputs!$B$42) -> 8.82 | E36: =(Inputs!E$48-Inputs!E$50)*(1+Inputs!$B$42) -> 7.14
A37: U.S. facility operations ($m) | B37: =Inputs!B$49*Inputs!$B$40*(1+Scenarios!$C$9)+Inputs!B$49*(1-Inputs!$B$40)*(1+B33) -> 398.77895 | C37: =Inputs!C$49*Inputs!$B$40*(1+Scenarios!$C$9)+Inputs!C$49*(1-Inputs!$B$40)*(1+C33) -> 395.67678 | D37: =Inputs!D$49*Inputs!$B$40*(1+Scenarios!$C$9)+Inputs!D$49*(1-Inputs!$B$40)*(1+D33) -> 419.99379 | E37: =Inputs!E$49*Inputs!$B$40*(1+Scenarios!$C$9)+Inputs!E$49*(1-Inputs!$B$40)*(1+E33) -> 434.69775 | F37: =SUM(B37:E37) -> 1649.1473
A38: U.S. G&A ($m) | B38: =Inputs!B$51*(1+Inputs!$B$42) -> 93.66 | C38: =Inputs!C$51*(1+Inputs!$B$42) -> 92.82 | D38: =Inputs!D$51*(1+Inputs!$B$42) -> 98.385 | E38: =Inputs!E$51*(1+Inputs!$B$42) -> 96.285 | F38: =SUM(B38:E38) -> 381.15
A39: U.S. operating income ($m) | B39: =B34+B36-B37-B38 -> 326.08138 | C39: =C34+C36-C37-C38 -> 294.52839 | D39: =D34+D36-D37-D38 -> 339.42894 | E39: =E34+E36-E37-E38 -> 312.2858 | F39: =SUM(B39:E39) -> 1272.3245
A40: U.S. operating margin | B40: =B39/(B34+B35) -> 0.3571458 | C40: =C39/(C34+C35) -> 0.33308453 | D40: =D39/(D34+D35) -> 0.35292562 | E40: =E39/(E34+E35) -> 0.32725663 | F40: =F39/(F34+F35) -> 0.34264198
A41: International operating income ($m) | B41: =Inputs!B$52*(1+Inputs!$B$43) -> 61.27 | C41: =Inputs!C$52*(1+Inputs!$B$43) -> 51.92 | D41: =Inputs!D$52*(1+Inputs!$B$43) -> 81.18 | E41: =Inputs!E$52*(1+Inputs!$B$43) -> 62.48 | F41: =SUM(B41:E41) -> 256.85
A42: International revenue ($m) | B42: =Inputs!B$53*(1+Inputs!$B$43) -> 222.64 | C42: =Inputs!C$53*(1+Inputs!$B$43) -> 220.11 | D42: =Inputs!D$53*(1+Inputs!$B$43) -> 257.62 | E42: =Inputs!E$53*(1+Inputs!$B$43) -> 244.2 | F42: =SUM(B42:E42) -> 944.57
A43: Consolidated operating margin, ex-ACV | B43: =(B39+B41)/(B34+B35+B42) -> 0.34108031 | C43: =(C39+C41)/(C34+C35+C42) -> 0.31371102 | D43: =(D39+D41)/(D34+D35+D42) -> 0.34493736 | E43: =(E39+E41)/(E34+E35+E42) -> 0.31270782 | F43: =(F39+F41)/(F34+F35+F42) -> 0.32830073
...

Sheet Valuation
A1: Valuation at the planned exit: mid-February 2027 (after Q2 FY27 results)
A2: Value = PV of distributions from year-1 (NTM) and year-2 earnings, years 3-5 at g and a Gordon terminal, discounted at the cost of equity; ex-interest earnings, with net cash at the valuation date added. Justified P/E = ex-cash value / NTM EPS (derived from growth, ROIC and cost of equity, not selected). Explicit-period payout ratios are linked to each year's modeled EPS growth and incremental ROIC; normalized payout is used only after the recovery period.
A3: Valuation date: mid-February 2027, following Q2 FY27 results
A4: Forward earnings basis: NTM = Q3 FY27 + Q4 FY27 (modeled, incl. ACV) + Q1 FY28 + Q2 FY28 (each = the matching FY27 quarter's core operating EPS × (1 + FY28 growth) + ¼ of the FY28 ACV contribution ex-interest); ex-interest. Year 2 = Q3 FY28 - Q2 FY29.
A6: EPS by world: FY27 and FY28 (FY28 = standalone + explicit ACV)
A7: Line | B7: W1 Loss deepens | C7: W2 FY27 trough / FY28 normalizes | D7: W3 Cycle turns / ACV improves | E7: W4 Street right / share recapture
A8: Team scenario probability | B8: =Scenarios!B$14 -> 0.2 | C8: =Scenarios!C$14 -> 0.45 | D8: =Scenarios!D$14 -> 0.2 | E8: =Scenarios!E$14 -> 0.15
A9: FY27 EPS ex-ACV ($/sh) | B9: =EPS_Build!$F$21 -> 1.2792888 | C9: =EPS_Build!$F$46 -> 1.4520874 | D9: =EPS_Build!$F$71 -> 1.6104159 | E9: =EPS_Build!$F$96 -> 1.7054339
A10: FY27 modeled ACV impact ($/sh) | B10: =EPS_Build!F25 -> -0.09501073 | C10: =EPS_Build!F50 -> -0.069098712 | D10: =EPS_Build!F75 -> -0.043186695 | E10: =EPS_Build!F100 -> -0.043186695
A11: FY27 GAAP EPS incl. ACV ($/sh) | B11: =EPS_Build!$F$24 -> 1.184278 | C11: =EPS_Build!$F$49 -> 1.3829887 | D11: =EPS_Build!$F$74 -> 1.5672292 | E11: =EPS_Build!$F$99 -> 1.6622472
A12: FY28 standalone CPRT EPS before ACV ($/sh) | B12: =EPS_Build!F19*(1+Scenarios!B$15)+Inputs!$B$12*4*(1-Inputs!$B$8)/Inputs!$B$7 -> 1.3252088 | C12: =EPS_Build!F44*(1+Scenarios!C$15)+Inputs!$B$12*4*(1-Inputs!$B$8)/Inputs!$B$7 -> 1.6105834 | D12: =EPS_Build!F69*(1+Scenarios!D$15)+Inputs!$B$12*4*(1-Inputs!$B$8)/Inputs!$B$7 -> 1.876659 | E12: =EPS_Build!F94*(1+Scenarios!E$15)+Inputs!$B$12*4*(1-Inputs!$B$8)/Inputs!$B$7 -> 1.9415558
A13: FY28 ACV contribution ($/sh, team estimate) | B13: =Scenarios!B$13 -> 0 | C13: =Scenarios!C$13 -> 0.02 | D13: =Scenarios!D$13 -> 0.04 | E13: =Scenarios!E$13 -> 0.02
A14: FY28 EPS incl. ACV ($/sh) | B14: =B12+B13 -> 1.3252088 | C14: =C12+C13 -> 1.6305834 | D14: =D12+D13 -> 1.916659 | E14: =E12+E13 -> 1.9615558
A17: Forward earnings bridge at the valuation date (ex-interest, $/sh)
A18: Line | B18: W1 Loss deepens | C18: W2 FY27 trough / FY28 normalizes | D18: W3 Cycle turns / ACV improves | E18: W4 Street right / share recapture
A19: Q3 FY27 (Feb-Apr 27) ex-interest EPS incl. ACV | B19: =EPS_Build!D26 -> 0.2939636 | C19: =EPS_Build!D51 -> 0.34688326 | D19: =EPS_Build!D76 -> 0.39592849 | E19: =EPS_Build!D101 -> 0.42059118
A20: Q4 FY27 (May-Jul 27) ex-interest EPS incl. ACV | B20: =EPS_Build!E26 -> 0.25627402 | C20: =EPS_Build!E51 -> 0.30728698 | D20: =EPS_Build!E76 -> 0.354925 | E20: =EPS_Build!E101 -> 0.37928052
A21: FY28 ACV contribution ex-interest, per quarter | B21: =(Scenarios!B$13+(Inputs!$B$12-Scenarios!B$12)*4*(1-Inputs!$B$8)/Inputs!$B$7)/4 -> 0.013819742 | C21: =(Scenarios!C$13+(Inputs!$B$12-Scenarios!C$12)*4*(1-Inputs!$B$8)/Inputs!$B$7)/4 -> 0.016228541 | D21: =(Scenarios!D$13+(Inputs!$B$12-Scenarios!D$12)*4*(1-Inputs!$B$8)/Inputs!$B$7)/4 -> 0.018637339 | E21: =(Scenarios!E$13+(Inputs!$B$12-Scenarios!E$12)*4*(1-Inputs!$B$8)/Inputs!$B$7)/4 -> 0.013637339
A22: Q1 FY28 (Aug-Oct 27) ex-interest EPS | B22: =EPS_Build!B19*(1+Scenarios!B$15)+B21 -> 0.31690749 | C22: =EPS_Build!B44*(1+Scenarios!C$15)+C21 -> 0.39094528 | D22: =EPS_Build!B69*(1+Scenarios!D$15)+D21 -> 0.45995487 | E22: =EPS_Build!B94*(1+Scenarios!E$15)+E21 -> 0.47087182
A23: Q2 FY28 (Nov 27-Jan 28) ex-interest EPS | B23: =EPS_Build!C19*(1+Scenarios!B$15)+B21 -> 0.28210226 | C23: =EPS_Build!C44*(1+Scenarios!C$15)+C21 -> 0.35137647 | D23: =EPS_Build!C69*(1+Scenarios!D$15)+D21 -> 0.41630006 | E23: =EPS_Build!C94*(1+Scenarios!E$15)+E21 -> 0.42695277
A24: NTM ex-interest EPS at mid-Feb 2027 (year 1) | B24: =B19+B20+B22+B23 -> 1.1492474 | C24: =C19+C20+C22+C23 -> 1.396492 | D24: =D19+D20+D22+D23 -> 1.6271084 | E24: =E19+E20+E22+E23 -> 1.6976963
A25: Year 2 ex-interest EPS (Q3 FY28 - Q2 FY29) | B25: =(EPS_Build!D19+EPS_Build!E19)*(1+Scenarios!B$15)+2*B21+(B22+B23)*(1+Scenarios!B$16) -> 1.2671705 | C25: =(EPS_Build!D44+EPS_Build!E44)*(1+Scenarios!C$15)+2*C21+(C22+C23)*(1+Scenarios!C$16) -> 1.5887493 | D25: =(EPS_Build!D69+EPS_Build!E69)*(1+Scenarios!D$15)+2*D21+(D22+D23)*(1+Scenarios!D$16) -> 1.8987838 | E25: =(EPS_Build!D94+EPS_Build!E94)*(1+Scenarios!E$15)+2*E21+(E22+E23)*(1+Scenarios!E$16) -> 1.9546001
A26: Year-2 growth (FY28 recovery completes) | B26: =B25/B24-1 -> 0.10260902 | C26: =C25/C24-1 -> 0.13767163 | D26: =D25/D24-1 -> 0.1669682 | E26: =E25/E24-1 -> 0.15132493
A29: Valuation
A30: Line | B30: W1 Loss deepens | C30: W2 FY27 trough / FY28 normalizes | D30: W3 Cycle turns / ACV improves | E30: W4 Street right / share recapture
A31: EPS growth, years 3-5 and terminal fade start (g) | B31: =Scenarios!B$16 -> 0.03 | C31: =Scenarios!C$16 -> 0.06 | D31: =Scenarios!D$16 -> 0.09 | E31: =Scenarios!E$16 -> 0.1
A32: Incremental ROIC | B32: =Scenarios!B$17 -> 0.15 | C32: =Scenarios!C$17 -> 0.2 | D32: =Scenarios!D$17 -> 0.25 | E32: =Scenarios!E$17 -> 0.25
A33: Cost of equity (Inputs) | B33: =Inputs!$B$34 -> 0.0974 | C33: =Inputs!$B$34 -> 0.0974 | D33: =Inputs!$B$34 -> 0.0974 | E33: =Inputs!$B$34 -> 0.0974
A34: Terminal growth (Inputs) | B34: =Inputs!$B$32 -> 0.03 | C34: =Inputs!$B$32 -> 0.03 | D34: =Inputs!$B$32 -> 0.03 | E34: =Inputs!$B$32 -> 0.03
A35: Year-1 payout = 1 − g1 / ROIC (g1 = year-2 growth above) | B35: =1-B26/B32 -> 0.31593988 | C35: =1-C26/C32 -> 0.31164184 | D35: =1-D26/D32 -> 0.33212718 | E35: =1-E26/E32 -> 0.39470028
A36: Normalized payout, years 2-5 = 1 − g / ROIC | B36: =1-B31/B32 -> 0.8 | C36: =1-C31/C32 -> 0.7 | D36: =1-D31/D32 -> 0.64 | E36: =1-E31/E32 -> 0.6
A37: PV of years 1-5 distributions ($/sh) | B37: =B35*B24/(1+B33)+(1-B31/B32)*(B25/(1+B33)^2+B25*(1+B31)/(1+B33)^3+B25*(1+B31)^2/(1+B33)^4+B25*(1+B31)^3/(1+B33)^5) -> 3.4002663 | C37: =C35*C24/(1+C33)+(1-C31/C32)*(C25/(1+C33)^2+C25*(1+C31)/(1+C33)^3+C25*(1+C31)^2/(1+C33)^4+C25*(1+C31)^3/(1+C33)^5) -> 3.905884 | D37: =D35*D24/(1+D33)+(1-D31/D32)*(D25/(1+D33)^2+D25*(1+D31)/(1+D33)^3+D25*(1+D31)^2/(1+D33)^4+D25*(1+D31)^3/(1+D33)^5) -> 4.4881194 | E37: =E35*E24/(1+E33)+(1-E31/E32)*(E25/(1+E33)^2+E25*(1+E31)/(1+E33)^3+E25*(1+E31)^2/(1+E33)^4+E25*(1+E31)^3/(1+E33)^5) -> 4.5197581
A38: PV of terminal value ($/sh) | B38: =B25*(1+B31)^4*(1-B34/B32)/(B33-B34)/(1+B33)^5 -> 10.636268 | C38: =C25*(1+C31)^4*(1-C34/C32)/(C33-C34)/(1+C33)^5 -> 15.893264 | D38: =D25*(1+D31)^4*(1-D34/D32)/(D33-D34)/(1+D33)^5 -> 21.987685 | E38: =E25*(1+E31)^4*(1-E34/E32)/(E33-E34)/(1+E33)^5 -> 23.476138
A39: Ex-cash equity value ($/sh) | B39: =B37+B38 -> 14.036534 | C39: =C37+C38 -> 19.799148 | D39: =D37+D38 -> 26.475804 | E39: =E37+E38 -> 27.995896
A40: Justified ex-cash P/E on NTM EPS | B40: =B39/B24 -> 12.213675 | C40: =C39/C24 -> 14.177774 | D40: =D39/D24 -> 16.27169 | E40: =E39/E24 -> 16.490521
A41: Net cash per share at the valuation date ($/sh) | B41: =Inputs!$B$10*1000/Inputs!$B$7 -> 3.304721 | C41: =Inputs!$B$10*1000/Inputs!$B$7 -> 3.304721 | D41: =Inputs!$B$10*1000/Inputs!$B$7 -> 3.304721 | E41: =Inputs!$B$10*1000/Inputs!$B$7 -> 3.304721
A42: Value per share, mid-Feb 2027 ($/sh) | B42: =B39+B41 -> 17.341255 | C42: =C39+C41 -> 23.103869 | D42: =D39+D41 -> 29.780525 | E42: =E39+E41 -> 31.300617
A43: Stock return vs reference price | B43: =B42/Inputs!$B$6-1 -> -0.36455642 | C43: =C42/Inputs!$B$6-1 -> -0.15339433 | D43: =D42/Inputs!$B$6-1 -> 0.09126146 | E43: =E42/Inputs!$B$6-1 -> 0.14696287
A44: Short return | B44: =-B43 -> 0.36455642 | C44: =-C43 -> 0.15339433 | D44: =-D43 -> -0.09126146 | E44: =-E43 -> -0.14696287
A45: NTM after-tax interest per share ($/sh) | B45: =Scenarios!B$12*4*(1-Inputs!$B$8)/Inputs!$B$7 -> 0.076008584 | C45: =Scenarios!C$12*4*(1-Inputs!$B$8)/Inputs!$B$7 -> 0.086373391 | D45: =Scenarios!D$12*4*(1-Inputs!$B$8)/Inputs!$B$7 -> 0.096738197 | E45: =Scenarios!E$12*4*(1-Inputs!$B$8)/Inputs!$B$7 -> 0.096738197
...

Sheet Sensitivity
A1: Sensitivity (live formulas)
A2: Operating drivers first (lost-customer drag × fixed cost share), then valuation, ACV and share-count risks.
A4: Key operating sensitivity: lost-customer drag × fixed facility cost share (W2; all other drivers unchanged)
A5: Run-rate drag \ fixed share | B5: 45% | C5: 55% | D5: 65%
A6: Q1 FY27 EPS ex-ACV ($/sh)
A7: 10 pts drag | B7: =I73 -> 0.38581195 | C7: =I74 -> 0.38129607 | D7: =I75 -> 0.3767802
A8: 13 pts drag (W2 base) | B8: =I76 -> 0.37269106 | C8: =I77 -> 0.36739041 | D8: =I78 -> 0.36208976
A9: 16 pts drag | B9: =I79 -> 0.35957016 | C9: =I80 -> 0.35348474 | D9: =I81 -> 0.34739932
A11: FY27 EPS ex-ACV ($/sh)
A12: 10 pts drag | B12: =J73 -> 1.5238913 | C12: =J74 -> 1.508071 | D12: =J75 -> 1.4922508
A13: 13 pts drag (W2 base) | B13: =J76 -> 1.4712164 | C13: =J77 -> 1.4520874 | D13: =J78 -> 1.4329585
A14: 16 pts drag | B14: =J79 -> 1.4185415 | C14: =J80 -> 1.3961038 | D14: =J81 -> 1.3736662
A16: Base-case (W2) value ($/sh)
A17: 10 pts drag | B17: =M73 -> 24.154434 | C17: =M74 -> 23.921746 | D17: =M75 -> 23.689059
A18: 13 pts drag (W2 base) | B18: =M76 -> 23.384848 | C18: =M77 -> 23.103869 | D18: =M78 -> 22.822889
A19: 16 pts drag | B19: =M79 -> 22.615263 | C19: =M80 -> 22.285991 | D19: =M81 -> 21.956719
A21: Lost-customer drag (W2, fixed share 55%)
A22: Full-run-rate drag | B22: Q1 FY27 EPS | C22: FY27 EPS ex-ACV | D22: Base-case value | E22: Short return
A23: 10 pts (≈ W3 run-rate) | B23: =I74 -> 0.38129607 | C23: =J74 -> 1.508071 | D23: =M74 -> 23.921746 | E23: =-(D23/Inputs!$B$6-1) -> 0.12342447
A24: 13 pts (W2 base) | B24: =I77 -> 0.36739041 | C24: =J77 -> 1.4520874 | D24: =M77 -> 23.103869 | E24: =-(D24/Inputs!$B$6-1) -> 0.15339433
A25: 16 pts (≈ 60%-in-Q4 implied; W1) | B25: =I80 -> 0.35348474 | C25: =J80 -> 1.3961038 | D25: =M80 -> 22.285991 | E25: =-(D25/Inputs!$B$6-1) -> 0.18336419
A27: Diluted shares / buyback risk (W2; buybacks at $27.29 funded from cash, interest forgone)
A28: Diluted shares (m) | B28: Q1 FY27 EPS | C28: FY27 EPS ex-ACV | D28: Base-case value | E28: Short return
A29: 940m (v1 assumption) | B29: =I82 -> 0.36584602 | C29: =J82 -> 1.4460586 | D29: =M82 -> 23.141303 | E29: =-(D29/Inputs!$B$6-1) -> 0.15202261
A30: 932m (model: Q4 FY26 diluted WASO) | B30: =I83 -> 0.36739041 | C30: =J83 -> 1.4520874 | D30: =M83 -> 23.103869 | E30: =-(D30/Inputs!$B$6-1) -> 0.15339433
A31: 930m (modest buybacks) | B31: =I84 -> 0.36778066 | C31: =J84 -> 1.4536108 | D31: =M84 -> 23.09441 | E31: =-(D31/Inputs!$B$6-1) -> 0.15374095
A32: 920m (accelerated buybacks) | B32: =I85 -> 0.36975736 | C32: =J85 -> 1.4613273 | D32: =M85 -> 23.046497 | E32: =-(D32/Inputs!$B$6-1) -> 0.15549664
A34: Cost-of-equity shift (all four worlds revalued)
A35: Cost-of-equity shift | B35: Shift | C35: Cost of equity | D35: Base-case value | E35: Expected short return
A36: Cost of equity -1.0pt | B36: -0.01 | C36: =Inputs!$B$34+B36 -> 0.0874 | D36: =((1-((Valuation!$C$25)/(Valuation!$C$24)-1)/Valuation!$C$32)*(Valuation!$C$24)/(1+$C36)+(1-Valuation!$C$31/Valuation!$C$32)*((Valuation!$C$25)/(1+$C36)^2+(Valuation!$C$25)*(1+Valuation!$C$31)/(1+$C36)^3+(Valuation!$C$25)*(1+Valuation!$C$31)^2/(1+$C36)^4+(Valuation!$C$25)*(1+Valuation!$C$31)^3/(1+$C36)^5)+(Valuation!$C$25)*(1+Valuation!$C$31)^4*(1-Valuation!$C$34/Valuation!$C$32)/($C36-Valuation!$C$34)/(1+$C36)^5+Valuation!$C$41) -> 26.863424 | E36: =-(Valuation!B8*(((1-((Valuation!$B$25)/(Valuation!$B$24)-1)/Valuation!$B$32)*(Valuation!$B$24)/(1+$C36)+(1-Valuation!$B$31/Valuation!$B$32)*((Valuation!$B$25)/(1+$C36)^2+(Valuation!$B$25)*(1+Valuation!$B$31)/(1+$C36)^3+(Valuation!$B$25)*(1+Valuation!$B$31)^2/(1+$C36)^4+(Valuation!$B$25)*(1+Valuation!$B$31)^3/(1+$C36)^5)+(Valuation!$B$25)*(1+Valuation!$B$31)^4*(1-Valuation!$B$34/Valuation!$B$32)/($C36-Valuation!$B$34)/(1+$C36)^5+Valuation!$B$41)/Inputs!$B$6-1)+Valuation!C8*(((1-((Valuation!$C$25)/(Valuation!$C$24)-1)/Valuation!$C$32)*(Valuation!$C$24)/(1+$C36)+(1-Valuation!$C$31/Valuation!$C$32)*((Valuation!$C$25)/(1+$C36)^2+(Valuation!$C$25)*(1+Valuation!$C$31)/(1+$C36)^3+(Valuation!$C$25)*(1+Valuation!$C$31)^2/(1+$C36)^4+(Valuation!$C$25)*(1+Valuation!$C$31)^3/(1+$C36)^5)+(Valuation!$C$25)*(1+Valuation!$C$31)^4*(1-Valuation!$C$34/Valuation!$C$32)/($C36-Valuation!$C$34)/(1+$C36)^5+Valuation!$C$41)/Inputs!$B$6-1)+Valuation!D8*(((1-((Valuation!$D$25)/(Valuation!$D$24)-1)/Valuation!$D$32)*(Valuation!$D$24)/(1+$C36)+(1-Valuation!$D$31/Valuation!$D$32)*((Valuation!$D$25)/(1+$C36)^2+(Valuation!$D$25)*(1+Valuation!$D$31)/(1+$C36)^3+(Valuation!$D$25)*(1+Valuation!$D$31)^2/(1+$C36)^4+(Valuation!$D$25)*(1+Valuation!$D$31)^3/(1+$C36)^5)+(Valuation!$D$25)*(1+Valuation!$D$31)^4*(1-Valuation!$D$34/Valuation!$D$32)/($C36-Valuation!$D$34)/(1+$C36)^5+Valuation!$D$41)/Inputs!$B$6-1)+Valuation!E8*(((1-((Valuation!$E$25)/(Valuation!$E$24)-1)/Valuation!$E$32)*(Valuation!$E$24)/(1+$C36)+(1-Valuation!$E$31/Valuation!$E$32)*((Valuation!$E$25)/(1+$C36)^2+(Valuation!$E$25)*(1+Valuation!$E$31)/(1+$C36)^3+(Valuation!$E$25)*(1+Valuation!$E$31)^2/(1+$C36)^4+(Valuation!$E$25)*(1+Valuation!$E$31)^3/(1+$C36)^5)+(Valuation!$E$25)*(1+Valuation!$E$31)^4*(1-Valuation!$E$34/Valuation!$E$32)/($C36-Valuation!$E$34)/(1+$C36)^5+Valuation!$E$41)/Inputs!$B$6-1)) -> -0.047187182
A37: Cost of equity -0.5pt | B37: -0.005 | C37: =Inputs!$B$34+B37 -> 0.0924 | D37: =((1-((Valuation!$C$25)/(Valuation!$C$24)-1)/Valuation!$C$32)*(Valuation!$C$24)/(1+$C37)+(1-Valuation!$C$31/Valuation!$C$32)*((Valuation!$C$25)/(1+$C37)^2+(Valuation!$C$25)*(1+Valuation!$C$31)/(1+$C37)^3+(Valuation!$C$25)*(1+Valuation!$C$31)^2/(1+$C37)^4+(Valuation!$C$25)*(1+Valuation!$C$31)^3/(1+$C37)^5)+(Valuation!$C$25)*(1+Valuation!$C$31)^4*(1-Valuation!$C$34/Valuation!$C$32)/($C37-Valuation!$C$34)/(1+$C37)^5+Valuation!$C$41) -> 24.831545 | E37: =-(Valuation!B8*(((1-((Valuation!$B$25)/(Valuation!$B$24)-1)/Valuation!$B$32)*(Valuation!$B$24)/(1+$C37)+(1-Valuation!$B$31/Valuation!$B$32)*((Valuation!$B$25)/(1+$C37)^2+(Valuation!$B$25)*(1+Valuation!$B$31)/(1+$C37)^3+(Valuation!$B$25)*(1+Valuation!$B$31)^2/(1+$C37)^4+(Valuation!$B$25)*(1+Valuation!$B$31)^3/(1+$C37)^5)+(Valuation!$B$25)*(1+Valuation!$B$31)^4*(1-Valuation!$B$34/Valuation!$B$32)/($C37-Valuation!$B$34)/(1+$C37)^5+Valuation!$B$41)/Inputs!$B$6-1)+Valuation!C8*(((1-((Valuation!$C$25)/(Valuation!$C$24)-1)/Valuation!$C$32)*(Valuation!$C$24)/(1+$C37)+(1-Valuation!$C$31/Valuation!$C$32)*((Valuation!$C$25)/(1+$C37)^2+(Valuation!$C$25)*(1+Valuation!$C$31)/(1+$C37)^3+(Valuation!$C$25)*(1+Valuation!$C$31)^2/(1+$C37)^4+(Valuation!$C$25)*(1+Valuation!$C$31)^3/(1+$C37)^5)+(Valuation!$C$25)*(1+Valuation!$C$31)^4*(1-Valuation!$C$34/Valuation!$C$32)/($C37-Valuation!$C$34)/(1+$C37)^5+Valuation!$C$41)/Inputs!$B$6-1)+Valuation!D8*(((1-((Valuation!$D$25)/(Valuation!$D$24)-1)/Valuation!$D$32)*(Valuation!$D$24)/(1+$C37)+(1-Valuation!$D$31/Valuation!$D$32)*((Valuation!$D$25)/(1+$C37)^2+(Valuation!$D$25)*(1+Valuation!$D$31)/(1+$C37)^3+(Valuation!$D$25)*(1+Valuation!$D$31)^2/(1+$C37)^4+(Valuation!$D$25)*(1+Valuation!$D$31)^3/(1+$C37)^5)+(Valuation!$D$25)*(1+Valuation!$D$31)^4*(1-Valuation!$D$34/Valuation!$D$32)/($C37-Valuation!$D$34)/(1+$C37)^5+Valuation!$D$41)/Inputs!$B$6-1)+Valuation!E8*(((1-((Valuation!$E$25)/(Valuation!$E$24)-1)/Valuation!$E$32)*(Valuation!$E$24)/(1+$C37)+(1-Valuation!$E$31/Valuation!$E$32)*((Valuation!$E$25)/(1+$C37)^2+(Valuation!$E$25)*(1+Valuation!$E$31)/(1+$C37)^3+(Valuation!$E$25)*(1+Valuation!$E$31)^2/(1+$C37)^4+(Valuation!$E$25)*(1+Valuation!$E$31)^3/(1+$C37)^5)+(Valuation!$E$25)*(1+Valuation!$E$31)^4*(1-Valuation!$E$34/Valuation!$E$32)/($C37-Valuation!$E$34)/(1+$C37)^5+Valuation!$E$41)/Inputs!$B$6-1)) -> 0.033257222
A38: Cost of equity (base) | B38: 0 | C38: =Inputs!$B$34+B38 -> 0.0974 | D38: =((1-((Valuation!$C$25)/(Valuation!$C$24)-1)/Valuation!$C$32)*(Valuation!$C$24)/(1+$C38)+(1-Valuation!$C$31/Valuation!$C$32)*((Valuation!$C$25)/(1+$C38)^2+(Valuation!$C$25)*(1+Valuation!$C$31)/(1+$C38)^3+(Valuation!$C$25)*(1+Valuation!$C$31)^2/(1+$C38)^4+(Valuation!$C$25)*(1+Valuation!$C$31)^3/(1+$C38)^5)+(Valuation!$C$25)*(1+Valuation!$C$31)^4*(1-Valuation!$C$34/Valuation!$C$32)/($C38-Valuation!$C$34)/(1+$C38)^5+Valuation!$C$41) -> 23.103869 | E38: =-(Valuation!B8*(((1-((Valuation!$B$25)/(Valuation!$B$24)-1)/Valuation!$B$32)*(Valuation!$B$24)/(1+$C38)+(1-Valuation!$B$31/Valuation!$B$32)*((Valuation!$B$25)/(1+$C38)^2+(Valuation!$B$25)*(1+Valuation!$B$31)/(1+$C38)^3+(Valuation!$B$25)*(1+Valuation!$B$31)^2/(1+$C38)^4+(Valuation!$B$25)*(1+Valuation!$B$31)^3/(1+$C38)^5)+(Valuation!$B$25)*(1+Valuation!$B$31)^4*(1-Valuation!$B$34/Valuation!$B$32)/($C38-Valuation!$B$34)/(1+$C38)^5+Valuation!$B$41)/Inputs!$B$6-1)+Valuation!C8*(((1-((Valuation!$C$25)/(Valuation!$C$24)-1)/Valuation!$C$32)*(Valuation!$C$24)/(1+$C38)+(1-Valuation!$C$31/Valuation!$C$32)*((Valuation!$C$25)/(1+$C38)^2+(Valuation!$C$25)*(1+Valuation!$C$31)/(1+$C38)^3+(Valuation!$C$25)*(1+Valuation!$C$31)^2/(1+$C38)^4+(Valuation!$C$25)*(1+Valuation!$C$31)^3/(1+$C38)^5)+(Valuation!$C$25)*(1+Valuation!$C$31)^4*(1-Valuation!$C$34/Valuation!$C$32)/($C38-Valuation!$C$34)/(1+$C38)^5+Valuation!$C$41)/Inputs!$B$6-1)+Valuation!D8*(((1-((Valuation!$D$25)/(Valuation!$D$24)-1)/Valuation!$D$32)*(Valuation!$D$24)/(1+$C38)+(1-Valuation!$D$31/Valuation!$D$32)*((Valuation!$D$25)/(1+$C38)^2+(Valuation!$D$25)*(1+Valuation!$D$31)/(1+$C38)^3+(Valuation!$D$25)*(1+Valuation!$D$31)^2/(1+$C38)^4+(Valuation!$D$25)*(1+Valuation!$D$31)^3/(1+$C38)^5)+(Valuation!$D$25)*(1+Valuation!$D$31)^4*(1-Valuation!$D$34/Valuation!$D$32)/($C38-Valuation!$D$34)/(1+$C38)^5+Valuation!$D$41)/Inputs!$B$6-1)+Valuation!E8*(((1-((Valuation!$E$25)/(Valuation!$E$24)-1)/Valuation!$E$32)*(Valuation!$E$24)/(1+$C38)+(1-Valuation!$E$31/Valuation!$E$32)*((Valuation!$E$25)/(1+$C38)^2+(Valuation!$E$25)*(1+Valuation!$E$31)/(1+$C38)^3+(Valuation!$E$25)*(1+Valuation!$E$31)^2/(1+$C38)^4+(Valuation!$E$25)*(1+Valuation!$E$31)^3/(1+$C38)^5)+(Valuation!$E$25)*(1+Valuation!$E$31)^4*(1-Valuation!$E$34/Valuation!$E$32)/($C38-Valuation!$E$34)/(1+$C38)^5+Valuation!$E$41)/Inputs!$B$6-1)) -> 0.10164201
A39: Cost of equity +0.5pt | B39: 0.005 | C39: =Inputs!$B$34+B39 -> 0.1024 | D39: =((1-((Valuation!$C$25)/(Valuation!$C$24)-1)/Valuation!$C$32)*(Valuation!$C$24)/(1+$C39)+(1-Valuation!$C$31/Valuation!$C$32)*((Valuation!$C$25)/(1+$C39)^2+(Valuation!$C$25)*(1+Valuation!$C$31)/(1+$C39)^3+(Valuation!$C$25)*(1+Valuation!$C$31)^2/(1+$C39)^4+(Valuation!$C$25)*(1+Valuation!$C$31)^3/(1+$C39)^5)+(Valuation!$C$25)*(1+Valuation!$C$31)^4*(1-Valuation!$C$34/Valuation!$C$32)/($C39-Valuation!$C$34)/(1+$C39)^5+Valuation!$C$41) -> 21.617298 | E39: =-(Valuation!B8*(((1-((Valuation!$B$25)/(Valuation!$B$24)-1)/Valuation!$B$32)*(Valuation!$B$24)/(1+$C39)+(1-Valuation!$B$31/Valuation!$B$32)*((Valuation!$B$25)/(1+$C39)^2+(Valuation!$B$25)*(1+Valuation!$B$31)/(1+$C39)^3+(Valuation!$B$25)*(1+Valuation!$B$31)^2/(1+$C39)^4+(Valuation!$B$25)*(1+Valuation!$B$31)^3/(1+$C39)^5)+(Valuation!$B$25)*(1+Valuation!$B$31)^4*(1-Valuation!$B$34/Valuation!$B$32)/($C39-Valuation!$B$34)/(1+$C39)^5+Valuation!$B$41)/Inputs!$B$6-1)+Valuation!C8*(((1-((Valuation!$C$25)/(Valuation!$C$24)-1)/Valuation!$C$32)*(Valuation!$C$24)/(1+$C39)+(1-Valuation!$C$31/Valuation!$C$32)*((Valuation!$C$25)/(1+$C39)^2+(Valuation!$C$25)*(1+Valuation!$C$31)/(1+$C39)^3+(Valuation!$C$25)*(1+Valuation!$C$31)^2/(1+$C39)^4+(Valuation!$C$25)*(1+Valuation!$C$31)^3/(1+$C39)^5)+(Valuation!$C$25)*(1+Valuation!$C$31)^4*(1-Valuation!$C$34/Valuation!$C$32)/($C39-Valuation!$C$34)/(1+$C39)^5+Valuation!$C$41)/Inputs!$B$6-1)+Valuation!D8*(((1-((Valuation!$D$25)/(Valuation!$D$24)-1)/Valuation!$D$32)*(Valuation!$D$24)/(1+$C39)+(1-Valuation!$D$31/Valuation!$D$32)*((Valuation!$D$25)/(1+$C39)^2+(Valuation!$D$25)*(1+Valuation!$D$31)/(1+$C39)^3+(Valuation!$D$25)*(1+Valuation!$D$31)^2/(1+$C39)^4+(Valuation!$D$25)*(1+Valuation!$D$31)^3/(1+$C39)^5)+(Valuation!$D$25)*(1+Valuation!$D$31)^4*(1-Valuation!$D$34/Valuation!$D$32)/($C39-Valuation!$D$34)/(1+$C39)^5+Valuation!$D$41)/Inputs!$B$6-1)+Valuation!E8*(((1-((Valuation!$E$25)/(Valuation!$E$24)-1)/Valuation!$E$32)*(Valuation!$E$24)/(1+$C39)+(1-Valuation!$E$31/Valuation!$E$32)*((Valuation!$E$25)/(1+$C39)^2+(Valuation!$E$25)*(1+Valuation!$E$31)/(1+$C39)^3+(Valuation!$E$25)*(1+Valuation!$E$31)^2/(1+$C39)^4+(Valuation!$E$25)*(1+Valuation!$E$31)^3/(1+$C39)^5)+(Valuation!$E$25)*(1+Valuation!$E$31)^4*(1-Valuation!$E$34/Valuation!$E$32)/($C39-Valuation!$E$34)/(1+$C39)^5+Valuation!$E$41)/Inputs!$B$6-1)) -> 0.16046904
A40: Cost of equity +1.0pt | B40: 0.01 | C40: =Inputs!$B$34+B40 -> 0.1074 | D40: =((1-((Valuation!$C$25)/(Valuation!$C$24)-1)/Valuation!$C$32)*(Valuation!$C$24)/(1+$C40)+(1-Valuation!$C$31/Valuation!$C$32)*((Valuation!$C$25)/(1+$C40)^2+(Valuation!$C$25)*(1+Valuation!$C$31)/(1+$C40)^3+(Valuation!$C$25)*(1+Valuation!$C$31)^2/(1+$C40)^4+(Valuation!$C$25)*(1+Valuation!$C$31)^3/(1+$C40)^5)+(Valuation!$C$25)*(1+Valuation!$C$31)^4*(1-Valuation!$C$34/Valuation!$C$32)/($C40-Valuation!$C$34)/(1+$C40)^5+Valuation!$C$41) -> 20.325041 | E40: =-(Valuation!B8*(((1-((Valuation!$B$25)/(Valuation!$B$24)-1)/Valuation!$B$32)*(Valuation!$B$24)/(1+$C40)+(1-Valuation!$B$31/Valuation!$B$32)*((Valuation!$B$25)/(1+$C40)^2+(Valuation!$B$25)*(1+Valuation!$B$31)/(1+$C40)^3+(Valuation!$B$25)*(1+Valuation!$B$31)^2/(1+$C40)^4+(Valuation!$B$25)*(1+Valuation!$B$31)^3/(1+$C40)^5)+(Valuation!$B$25)*(1+Valuation!$B$31)^4*(1-Valuation!$B$34/Valuation!$B$32)/($C40-Valuation!$B$34)/(1+$C40)^5+Valuation!$B$41)/Inputs!$B$6-1)+Valuation!C8*(((1-((Valuation!$C$25)/(Valuation!$C$24)-1)/Valuation!$C$32)*(Valuation!$C$24)/(1+$C40)+(1-Valuation!$C$31/Valuation!$C$32)*((Valuation!$C$25)/(1+$C40)^2+(Valuation!$C$25)*(1+Valuation!$C$31)/(1+$C40)^3+(Valuation!$C$25)*(1+Valuation!$C$31)^2/(1+$C40)^4+(Valuation!$C$25)*(1+Valuation!$C$31)^3/(1+$C40)^5)+(Valuation!$C$25)*(1+Valuation!$C$31)^4*(1-Valuation!$C$34/Valuation!$C$32)/($C40-Valuation!$C$34)/(1+$C40)^5+Valuation!$C$41)/Inputs!$B$6-1)+Valuation!D8*(((1-((Valuation!$D$25)/(Valuation!$D$24)-1)/Valuation!$D$32)*(Valuation!$D$24)/(1+$C40)+(1-Valuation!$D$31/Valuation!$D$32)*((Valuation!$D$25)/(1+$C40)^2+(Valuation!$D$25)*(1+Valuation!$D$31)/(1+$C40)^3+(Valuation!$D$25)*(1+Valuation!$D$31)^2/(1+$C40)^4+(Valuation!$D$25)*(1+Valuation!$D$31)^3/(1+$C40)^5)+(Valuation!$D$25)*(1+Valuation!$D$31)^4*(1-Valuation!$D$34/Valuation!$D$32)/($C40-Valuation!$D$34)/(1+$C40)^5+Valuation!$D$41)/Inputs!$B$6-1)+Valuation!E8*(((1-((Valuation!$E$25)/(Valuation!$E$24)-1)/Valuation!$E$32)*(Valuation!$E$24)/(1+$C40)+(1-Valuation!$E$31/Valuation!$E$32)*((Valuation!$E$25)/(1+$C40)^2+(Valuation!$E$25)*(1+Valuation!$E$31)/(1+$C40)^3+(Valuation!$E$25)*(1+Valuation!$E$31)^2/(1+$C40)^4+(Valuation!$E$25)*(1+Valuation!$E$31)^3/(1+$C40)^5)+(Valuation!$E$25)*(1+Valuation!$E$31)^4*(1-Valuation!$E$34/Valuation!$E$32)/($C40-Valuation!$E$34)/(1+$C40)^5+Valuation!$E$41)/Inputs!$B$6-1)) -> 0.21159359
A42: FY28 ACV EPS contribution (applied to all worlds)
A43: FY28 ACV contribution ($/sh) | B43: −$0.04 | C43: $0.00 | D43: +$0.02 | E43: +$0.04
A44: W2 FY28 EPS incl. ACV ($/sh) | B44: =Valuation!$C$12+-0.04 -> 1.5705834 | C44: =Valuation!$C$12+0 -> 1.6105834 | D44: =Valuation!$C$12+0.02 -> 1.6305834 | E44: =Valuation!$C$12+0.04 -> 1.6505834
A45: Base-case (W2) value ($/sh) | B45: =((1-((Valuation!$C$25+(-0.04-Valuation!$C$13)/2*(2+Valuation!$C$31))/(Valuation!$C$24+(-0.04-Valuation!$C$13)/2)-1)/Valuation!$C$32)*(Valuation!$C$24+(-0.04-Valuation!$C$13)/2)/(1+Valuation!$C$33)+(1-Valuation!$C$31/Valuation!$C$32)*((Valuation!$C$25+(-0.04-Valuation!$C$13)/2*(2+Valuation!$C$31))/(1+Valuation!$C$33)^2+(Valuation!$C$25+(-0.04-Valuation!$C$13)/2*(2+Valuation!$C$31))*(1+Valuation!$C$31)/(1+Valuation!$C$33)^3+(Valuation!$C$25+(-0.04-Valuation!$C$13)/2*(2+Valuation!$C$31))*(1+Valuation!$C$31)^2/(1+Valuation!$C$33)^4+(Valuation!$C$25+(-0.04-Valuation!$C$13)/2*(2+Valuation!$C$31))*(1+Valuation!$C$31)^3/(1+Valuation!$C$33)^5)+(Valuation!$C$25+(-0.04-Valuation!$C$13)/2*(2+Valuation!$C$31))*(1+Valuation!$C$31)^4*(1-Valuation!$C$34/Valuation!$C$32)/(Valuation!$C$33-Valuation!$C$34)/(1+Valuation!$C$33)^5+Valuation!$C$41) -> 22.466688 | C45: =((1-((Valuation!$C$25+(0-Valuation!$C$13)/2*(2+Valuation!$C$31))/(Valuation!$C$24+(0-Valuation!$C$13)/2)-1)/Valuation!$C$32)*(Valuation!$C$24+(0-Valuation!$C$13)/2)/(1+Valuation!$C$33)+(1-Valuation!$C$31/Valuation!$C$32)*((Valuation!$C$25+(0-Valuation!$C$13)/2*(2+Valuation!$C$31))/(1+Valuation!$C$33)^2+(Valuation!$C$25+(0-Valuation!$C$13)/2*(2+Valuation!$C$31))*(1+Valuation!$C$31)/(1+Valuation!$C$33)^3+(Valuation!$C$25+(0-Valuation!$C$13)/2*(2+Valuation!$C$31))*(1+Valuation!$C$31)^2/(1+Valuation!$C$33)^4+(Valuation!$C$25+(0-Valuation!$C$13)/2*(2+Valuation!$C$31))*(1+Valuation!$C$31)^3/(1+Valuation!$C$33)^5)+(Valuation!$C$25+(0-Valuation!$C$13)/2*(2+Valuation!$C$31))*(1+Valuation!$C$31)^4*(1-Valuation!$C$34/Valuation!$C$32)/(Valuation!$C$33-Valuation!$C$34)/(1+Valuation!$C$33)^5+Valuation!$C$41) -> 22.891475 | D45: =((1-((Valuation!$C$25+(0.02-Valuation!$C$13)/2*(2+Valuation!$C$31))/(Valuation!$C$24+(0.02-Valuation!$C$13)/2)-1)/Valuation!$C$32)*(Valuation!$C$24+(0.02-Valuation!$C$13)/2)/(1+Valuation!$C$33)+(1-Valuation!$C$31/Valuation!$C$32)*((Valuation!$C$25+(0.02-Valuation!$C$13)/2*(2+Valuation!$C$31))/(1+Valuation!$C$33)^2+(Valuation!$C$25+(0.02-Valuation!$C$13)/2*(2+Valuation!$C$31))*(1+Valuation!$C$31)/(1+Valuation!$C$33)^3+(Valuation!$C$25+(0.02-Valuation!$C$13)/2*(2+Valuation!$C$31))*(1+Valuation!$C$31)^2/(1+Valuation!$C$33)^4+(Valuation!$C$25+(0.02-Valuation!$C$13)/2*(2+Valuation!$C$31))*(1+Valuation!$C$31)^3/(1+Valuation!$C$33)^5)+(Valuation!$C$25+(0.02-Valuation!$C$13)/2*(2+Valuation!$C$31))*(1+Valuation!$C$31)^4*(1-Valuation!$C$34/Valuation!$C$32)/(Valuation!$C$33-Valuation!$C$34)/(1+Valuation!$C$33)^5+Valuation!$C$41) -> 23.103869 | E45: =((1-((Valuation!$C$25+(0.04-Valuation!$C$13)/2*(2+Valuation!$C$31))/(Valuation!$C$24+(0.04-Valuation!$C$13)/2)-1)/Valuation!$C$32)*(Valuation!$C$24+(0.04-Valuation!$C$13)/2)/(1+Valuation!$C$33)+(1-Valuation!$C$31/Valuation!$C$32)*((Valuation!$C$25+(0.04-Valuation!$C$13)/2*(2+Valuation!$C$31))/(1+Valuation!$C$33)^2+(Valuation!$C$25+(0.04-Valuation!$C$13)/2*(2+Valuation!$C$31))*(1+Valuation!$C$31)/(1+Valuation!$C$33)^3+(Valuation!$C$25+(0.04-Valuation!$C$13)/2*(2+Valuation!$C$31))*(1+Valuation!$C$31)^2/(1+Valuation!$C$33)^4+(Valuation!$C$25+(0.04-Valuation!$C$13)/2*(2+Valuation!$C$31))*(1+Valuation!$C$31)^3/(1+Valuation!$C$33)^5)+(Valuation!$C$25+(0.04-Valuation!$C$13)/2*(2+Valuation!$C$31))*(1+Valuation!$C$31)^4*(1-Valuation!$C$34/Valuation!$C$32)/(Valuation!$C$33-Valuation!$C$34)/(1+Valuation!$C$33)^5+Valuation!$C$41) -> 23.316262
